Exception while resolving variable 'name' in template 'unknown'.
Traceback (most recent call last):
  File "C:\Users\mkvet\.virtualenvs\backend-ZuzYmCFP\lib\site-packages\django\core\handlers\exception.py", line 34, in inner
    response = get_response(request)
  File "C:\Users\mkvet\.virtualenvs\backend-ZuzYmCFP\lib\site-packages\django\core\handlers\base.py", line 111, in _get_response
    resolver_match = resolver.resolve(request.path_info)
  File "C:\Users\mkvet\.virtualenvs\backend-ZuzYmCFP\lib\site-packages\django\urls\resolvers.py", line 520, in resolve
    raise Resolver404({'tried': tried, 'path': new_path})
django.urls.exceptions.Resolver404: {'tried': [[<URLResolver <module 'shop.urls' from 'C:\\Users\\mkvet\\Documents\\Uni\\7_Semester\\WebDevSpecial\\puppy-webshop\\backend\\shop\\urls.py'> (None:None) 'shop/'>], [<URLResolver <URLPattern list> (admin:admin) 'admin/'>], [<URLPattern 'token-auth/'>], [<URLResolver <module 'rest_framework.urls' from 'C:\\Users\\mkvet\\.virtualenvs\\backend-ZuzYmCFP\\lib\\site-packages\\rest_framework\\urls.py'> (rest_framework:rest_framework) 'api-auth/'>], [<URLResolver <module 'letsencrypt.urls' from 'C:\\Users\\mkvet\\.virtualenvs\\backend-ZuzYmCFP\\lib\\site-packages\\letsencrypt\\urls.py'> (None:None) '\.well-known/'>]], 'path': ''}

During handling of the above exception, another exception occurred:

Traceback (most recent call last):
  File "C:\Users\mkvet\.virtualenvs\backend-ZuzYmCFP\lib\site-packages\django\template\base.py", line 829, in _resolve_lookup
    current = current[bit]
TypeError: 'URLResolver' object is not subscriptable

During handling of the above exception, another exception occurred:

Traceback (most recent call last):
  File "C:\Users\mkvet\.virtualenvs\backend-ZuzYmCFP\lib\site-packages\django\template\base.py", line 837, in _resolve_lookup
    current = getattr(current, bit)
AttributeError: 'URLResolver' object has no attribute 'name'

During handling of the above exception, another exception occurred:

Traceback (most recent call last):
  File "C:\Users\mkvet\.virtualenvs\backend-ZuzYmCFP\lib\site-packages\django\template\base.py", line 843, in _resolve_lookup
    current = current[int(bit)]
ValueError: invalid literal for int() with base 10: 'name'

During handling of the above exception, another exception occurred:

Traceback (most recent call last):
  File "C:\Users\mkvet\.virtualenvs\backend-ZuzYmCFP\lib\site-packages\django\template\base.py", line 850, in _resolve_lookup
    (bit, current))  # missing attribute
django.template.base.VariableDoesNotExist: Failed lookup for key [name] in <URLResolver <module 'shop.urls' from 'C:\\Users\\mkvet\\Documents\\Uni\\7_Semester\\WebDevSpecial\\puppy-webshop\\backend\\shop\\urls.py'> (None:None) 'shop/'>
Exception while resolving variable 'name' in template 'unknown'.
Traceback (most recent call last):
  File "C:\Users\mkvet\.virtualenvs\backend-ZuzYmCFP\lib\site-packages\django\core\handlers\exception.py", line 34, in inner
    response = get_response(request)
  File "C:\Users\mkvet\.virtualenvs\backend-ZuzYmCFP\lib\site-packages\django\core\handlers\base.py", line 111, in _get_response
    resolver_match = resolver.resolve(request.path_info)
  File "C:\Users\mkvet\.virtualenvs\backend-ZuzYmCFP\lib\site-packages\django\urls\resolvers.py", line 520, in resolve
    raise Resolver404({'tried': tried, 'path': new_path})
django.urls.exceptions.Resolver404: {'tried': [[<URLResolver <module 'shop.urls' from 'C:\\Users\\mkvet\\Documents\\Uni\\7_Semester\\WebDevSpecial\\puppy-webshop\\backend\\shop\\urls.py'> (None:None) 'shop/'>], [<URLResolver <URLPattern list> (admin:admin) 'admin/'>], [<URLPattern 'token-auth/'>], [<URLResolver <module 'rest_framework.urls' from 'C:\\Users\\mkvet\\.virtualenvs\\backend-ZuzYmCFP\\lib\\site-packages\\rest_framework\\urls.py'> (rest_framework:rest_framework) 'api-auth/'>], [<URLResolver <module 'letsencrypt.urls' from 'C:\\Users\\mkvet\\.virtualenvs\\backend-ZuzYmCFP\\lib\\site-packages\\letsencrypt\\urls.py'> (None:None) '\.well-known/'>]], 'path': ''}

During handling of the above exception, another exception occurred:

Traceback (most recent call last):
  File "C:\Users\mkvet\.virtualenvs\backend-ZuzYmCFP\lib\site-packages\django\template\base.py", line 829, in _resolve_lookup
    current = current[bit]
TypeError: 'URLResolver' object is not subscriptable

During handling of the above exception, another exception occurred:

Traceback (most recent call last):
  File "C:\Users\mkvet\.virtualenvs\backend-ZuzYmCFP\lib\site-packages\django\template\base.py", line 837, in _resolve_lookup
    current = getattr(current, bit)
AttributeError: 'URLResolver' object has no attribute 'name'

During handling of the above exception, another exception occurred:

Traceback (most recent call last):
  File "C:\Users\mkvet\.virtualenvs\backend-ZuzYmCFP\lib\site-packages\django\template\base.py", line 843, in _resolve_lookup
    current = current[int(bit)]
ValueError: invalid literal for int() with base 10: 'name'

During handling of the above exception, another exception occurred:

Traceback (most recent call last):
  File "C:\Users\mkvet\.virtualenvs\backend-ZuzYmCFP\lib\site-packages\django\template\base.py", line 850, in _resolve_lookup
    (bit, current))  # missing attribute
django.template.base.VariableDoesNotExist: Failed lookup for key [name] in <URLResolver <URLPattern list> (admin:admin) 'admin/'>
Exception while resolving variable 'name' in template 'unknown'.
Traceback (most recent call last):
  File "C:\Users\mkvet\.virtualenvs\backend-ZuzYmCFP\lib\site-packages\django\core\handlers\exception.py", line 34, in inner
    response = get_response(request)
  File "C:\Users\mkvet\.virtualenvs\backend-ZuzYmCFP\lib\site-packages\django\core\handlers\base.py", line 111, in _get_response
    resolver_match = resolver.resolve(request.path_info)
  File "C:\Users\mkvet\.virtualenvs\backend-ZuzYmCFP\lib\site-packages\django\urls\resolvers.py", line 520, in resolve
    raise Resolver404({'tried': tried, 'path': new_path})
django.urls.exceptions.Resolver404: {'tried': [[<URLResolver <module 'shop.urls' from 'C:\\Users\\mkvet\\Documents\\Uni\\7_Semester\\WebDevSpecial\\puppy-webshop\\backend\\shop\\urls.py'> (None:None) 'shop/'>], [<URLResolver <URLPattern list> (admin:admin) 'admin/'>], [<URLPattern 'token-auth/'>], [<URLResolver <module 'rest_framework.urls' from 'C:\\Users\\mkvet\\.virtualenvs\\backend-ZuzYmCFP\\lib\\site-packages\\rest_framework\\urls.py'> (rest_framework:rest_framework) 'api-auth/'>], [<URLResolver <module 'letsencrypt.urls' from 'C:\\Users\\mkvet\\.virtualenvs\\backend-ZuzYmCFP\\lib\\site-packages\\letsencrypt\\urls.py'> (None:None) '\.well-known/'>]], 'path': ''}

During handling of the above exception, another exception occurred:

Traceback (most recent call last):
  File "C:\Users\mkvet\.virtualenvs\backend-ZuzYmCFP\lib\site-packages\django\template\base.py", line 829, in _resolve_lookup
    current = current[bit]
TypeError: 'URLResolver' object is not subscriptable

During handling of the above exception, another exception occurred:

Traceback (most recent call last):
  File "C:\Users\mkvet\.virtualenvs\backend-ZuzYmCFP\lib\site-packages\django\template\base.py", line 837, in _resolve_lookup
    current = getattr(current, bit)
AttributeError: 'URLResolver' object has no attribute 'name'

During handling of the above exception, another exception occurred:

Traceback (most recent call last):
  File "C:\Users\mkvet\.virtualenvs\backend-ZuzYmCFP\lib\site-packages\django\template\base.py", line 843, in _resolve_lookup
    current = current[int(bit)]
ValueError: invalid literal for int() with base 10: 'name'

During handling of the above exception, another exception occurred:

Traceback (most recent call last):
  File "C:\Users\mkvet\.virtualenvs\backend-ZuzYmCFP\lib\site-packages\django\template\base.py", line 850, in _resolve_lookup
    (bit, current))  # missing attribute
django.template.base.VariableDoesNotExist: Failed lookup for key [name] in <URLResolver <module 'rest_framework.urls' from 'C:\\Users\\mkvet\\.virtualenvs\\backend-ZuzYmCFP\\lib\\site-packages\\rest_framework\\urls.py'> (rest_framework:rest_framework) 'api-auth/'>
Exception while resolving variable 'name' in template 'unknown'.
Traceback (most recent call last):
  File "C:\Users\mkvet\.virtualenvs\backend-ZuzYmCFP\lib\site-packages\django\core\handlers\exception.py", line 34, in inner
    response = get_response(request)
  File "C:\Users\mkvet\.virtualenvs\backend-ZuzYmCFP\lib\site-packages\django\core\handlers\base.py", line 111, in _get_response
    resolver_match = resolver.resolve(request.path_info)
  File "C:\Users\mkvet\.virtualenvs\backend-ZuzYmCFP\lib\site-packages\django\urls\resolvers.py", line 520, in resolve
    raise Resolver404({'tried': tried, 'path': new_path})
django.urls.exceptions.Resolver404: {'tried': [[<URLResolver <module 'shop.urls' from 'C:\\Users\\mkvet\\Documents\\Uni\\7_Semester\\WebDevSpecial\\puppy-webshop\\backend\\shop\\urls.py'> (None:None) 'shop/'>], [<URLResolver <URLPattern list> (admin:admin) 'admin/'>], [<URLPattern 'token-auth/'>], [<URLResolver <module 'rest_framework.urls' from 'C:\\Users\\mkvet\\.virtualenvs\\backend-ZuzYmCFP\\lib\\site-packages\\rest_framework\\urls.py'> (rest_framework:rest_framework) 'api-auth/'>], [<URLResolver <module 'letsencrypt.urls' from 'C:\\Users\\mkvet\\.virtualenvs\\backend-ZuzYmCFP\\lib\\site-packages\\letsencrypt\\urls.py'> (None:None) '\.well-known/'>]], 'path': ''}

During handling of the above exception, another exception occurred:

Traceback (most recent call last):
  File "C:\Users\mkvet\.virtualenvs\backend-ZuzYmCFP\lib\site-packages\django\template\base.py", line 829, in _resolve_lookup
    current = current[bit]
TypeError: 'URLResolver' object is not subscriptable

During handling of the above exception, another exception occurred:

Traceback (most recent call last):
  File "C:\Users\mkvet\.virtualenvs\backend-ZuzYmCFP\lib\site-packages\django\template\base.py", line 837, in _resolve_lookup
    current = getattr(current, bit)
AttributeError: 'URLResolver' object has no attribute 'name'

During handling of the above exception, another exception occurred:

Traceback (most recent call last):
  File "C:\Users\mkvet\.virtualenvs\backend-ZuzYmCFP\lib\site-packages\django\template\base.py", line 843, in _resolve_lookup
    current = current[int(bit)]
ValueError: invalid literal for int() with base 10: 'name'

During handling of the above exception, another exception occurred:

Traceback (most recent call last):
  File "C:\Users\mkvet\.virtualenvs\backend-ZuzYmCFP\lib\site-packages\django\template\base.py", line 850, in _resolve_lookup
    (bit, current))  # missing attribute
django.template.base.VariableDoesNotExist: Failed lookup for key [name] in <URLResolver <module 'letsencrypt.urls' from 'C:\\Users\\mkvet\\.virtualenvs\\backend-ZuzYmCFP\\lib\\site-packages\\letsencrypt\\urls.py'> (None:None) '\.well-known/'>
Not Found: /
"GET / HTTP/1.1" 404 2361
Exception while resolving variable 'name' in template 'unknown'.
Traceback (most recent call last):
  File "C:\Users\mkvet\.virtualenvs\backend-ZuzYmCFP\lib\site-packages\django\core\handlers\exception.py", line 34, in inner
    response = get_response(request)
  File "C:\Users\mkvet\.virtualenvs\backend-ZuzYmCFP\lib\site-packages\django\core\handlers\base.py", line 111, in _get_response
    resolver_match = resolver.resolve(request.path_info)
  File "C:\Users\mkvet\.virtualenvs\backend-ZuzYmCFP\lib\site-packages\django\urls\resolvers.py", line 520, in resolve
    raise Resolver404({'tried': tried, 'path': new_path})
django.urls.exceptions.Resolver404: {'tried': [[<URLResolver <module 'shop.urls' from 'C:\\Users\\mkvet\\Documents\\Uni\\7_Semester\\WebDevSpecial\\puppy-webshop\\backend\\shop\\urls.py'> (None:None) 'shop/'>], [<URLResolver <URLPattern list> (admin:admin) 'admin/'>], [<URLPattern 'token-auth/'>], [<URLResolver <module 'rest_framework.urls' from 'C:\\Users\\mkvet\\.virtualenvs\\backend-ZuzYmCFP\\lib\\site-packages\\rest_framework\\urls.py'> (rest_framework:rest_framework) 'api-auth/'>], [<URLResolver <module 'letsencrypt.urls' from 'C:\\Users\\mkvet\\.virtualenvs\\backend-ZuzYmCFP\\lib\\site-packages\\letsencrypt\\urls.py'> (None:None) '\.well-known/'>]], 'path': 'favicon.ico'}

During handling of the above exception, another exception occurred:

Traceback (most recent call last):
  File "C:\Users\mkvet\.virtualenvs\backend-ZuzYmCFP\lib\site-packages\django\template\base.py", line 829, in _resolve_lookup
    current = current[bit]
TypeError: 'URLResolver' object is not subscriptable

During handling of the above exception, another exception occurred:

Traceback (most recent call last):
  File "C:\Users\mkvet\.virtualenvs\backend-ZuzYmCFP\lib\site-packages\django\template\base.py", line 837, in _resolve_lookup
    current = getattr(current, bit)
AttributeError: 'URLResolver' object has no attribute 'name'

During handling of the above exception, another exception occurred:

Traceback (most recent call last):
  File "C:\Users\mkvet\.virtualenvs\backend-ZuzYmCFP\lib\site-packages\django\template\base.py", line 843, in _resolve_lookup
    current = current[int(bit)]
ValueError: invalid literal for int() with base 10: 'name'

During handling of the above exception, another exception occurred:

Traceback (most recent call last):
  File "C:\Users\mkvet\.virtualenvs\backend-ZuzYmCFP\lib\site-packages\django\template\base.py", line 850, in _resolve_lookup
    (bit, current))  # missing attribute
django.template.base.VariableDoesNotExist: Failed lookup for key [name] in <URLResolver <module 'shop.urls' from 'C:\\Users\\mkvet\\Documents\\Uni\\7_Semester\\WebDevSpecial\\puppy-webshop\\backend\\shop\\urls.py'> (None:None) 'shop/'>
Exception while resolving variable 'name' in template 'unknown'.
Traceback (most recent call last):
  File "C:\Users\mkvet\.virtualenvs\backend-ZuzYmCFP\lib\site-packages\django\core\handlers\exception.py", line 34, in inner
    response = get_response(request)
  File "C:\Users\mkvet\.virtualenvs\backend-ZuzYmCFP\lib\site-packages\django\core\handlers\base.py", line 111, in _get_response
    resolver_match = resolver.resolve(request.path_info)
  File "C:\Users\mkvet\.virtualenvs\backend-ZuzYmCFP\lib\site-packages\django\urls\resolvers.py", line 520, in resolve
    raise Resolver404({'tried': tried, 'path': new_path})
django.urls.exceptions.Resolver404: {'tried': [[<URLResolver <module 'shop.urls' from 'C:\\Users\\mkvet\\Documents\\Uni\\7_Semester\\WebDevSpecial\\puppy-webshop\\backend\\shop\\urls.py'> (None:None) 'shop/'>], [<URLResolver <URLPattern list> (admin:admin) 'admin/'>], [<URLPattern 'token-auth/'>], [<URLResolver <module 'rest_framework.urls' from 'C:\\Users\\mkvet\\.virtualenvs\\backend-ZuzYmCFP\\lib\\site-packages\\rest_framework\\urls.py'> (rest_framework:rest_framework) 'api-auth/'>], [<URLResolver <module 'letsencrypt.urls' from 'C:\\Users\\mkvet\\.virtualenvs\\backend-ZuzYmCFP\\lib\\site-packages\\letsencrypt\\urls.py'> (None:None) '\.well-known/'>]], 'path': 'favicon.ico'}

During handling of the above exception, another exception occurred:

Traceback (most recent call last):
  File "C:\Users\mkvet\.virtualenvs\backend-ZuzYmCFP\lib\site-packages\django\template\base.py", line 829, in _resolve_lookup
    current = current[bit]
TypeError: 'URLResolver' object is not subscriptable

During handling of the above exception, another exception occurred:

Traceback (most recent call last):
  File "C:\Users\mkvet\.virtualenvs\backend-ZuzYmCFP\lib\site-packages\django\template\base.py", line 837, in _resolve_lookup
    current = getattr(current, bit)
AttributeError: 'URLResolver' object has no attribute 'name'

During handling of the above exception, another exception occurred:

Traceback (most recent call last):
  File "C:\Users\mkvet\.virtualenvs\backend-ZuzYmCFP\lib\site-packages\django\template\base.py", line 843, in _resolve_lookup
    current = current[int(bit)]
ValueError: invalid literal for int() with base 10: 'name'

During handling of the above exception, another exception occurred:

Traceback (most recent call last):
  File "C:\Users\mkvet\.virtualenvs\backend-ZuzYmCFP\lib\site-packages\django\template\base.py", line 850, in _resolve_lookup
    (bit, current))  # missing attribute
django.template.base.VariableDoesNotExist: Failed lookup for key [name] in <URLResolver <URLPattern list> (admin:admin) 'admin/'>
Exception while resolving variable 'name' in template 'unknown'.
Traceback (most recent call last):
  File "C:\Users\mkvet\.virtualenvs\backend-ZuzYmCFP\lib\site-packages\django\core\handlers\exception.py", line 34, in inner
    response = get_response(request)
  File "C:\Users\mkvet\.virtualenvs\backend-ZuzYmCFP\lib\site-packages\django\core\handlers\base.py", line 111, in _get_response
    resolver_match = resolver.resolve(request.path_info)
  File "C:\Users\mkvet\.virtualenvs\backend-ZuzYmCFP\lib\site-packages\django\urls\resolvers.py", line 520, in resolve
    raise Resolver404({'tried': tried, 'path': new_path})
django.urls.exceptions.Resolver404: {'tried': [[<URLResolver <module 'shop.urls' from 'C:\\Users\\mkvet\\Documents\\Uni\\7_Semester\\WebDevSpecial\\puppy-webshop\\backend\\shop\\urls.py'> (None:None) 'shop/'>], [<URLResolver <URLPattern list> (admin:admin) 'admin/'>], [<URLPattern 'token-auth/'>], [<URLResolver <module 'rest_framework.urls' from 'C:\\Users\\mkvet\\.virtualenvs\\backend-ZuzYmCFP\\lib\\site-packages\\rest_framework\\urls.py'> (rest_framework:rest_framework) 'api-auth/'>], [<URLResolver <module 'letsencrypt.urls' from 'C:\\Users\\mkvet\\.virtualenvs\\backend-ZuzYmCFP\\lib\\site-packages\\letsencrypt\\urls.py'> (None:None) '\.well-known/'>]], 'path': 'favicon.ico'}

During handling of the above exception, another exception occurred:

Traceback (most recent call last):
  File "C:\Users\mkvet\.virtualenvs\backend-ZuzYmCFP\lib\site-packages\django\template\base.py", line 829, in _resolve_lookup
    current = current[bit]
TypeError: 'URLResolver' object is not subscriptable

During handling of the above exception, another exception occurred:

Traceback (most recent call last):
  File "C:\Users\mkvet\.virtualenvs\backend-ZuzYmCFP\lib\site-packages\django\template\base.py", line 837, in _resolve_lookup
    current = getattr(current, bit)
AttributeError: 'URLResolver' object has no attribute 'name'

During handling of the above exception, another exception occurred:

Traceback (most recent call last):
  File "C:\Users\mkvet\.virtualenvs\backend-ZuzYmCFP\lib\site-packages\django\template\base.py", line 843, in _resolve_lookup
    current = current[int(bit)]
ValueError: invalid literal for int() with base 10: 'name'

During handling of the above exception, another exception occurred:

Traceback (most recent call last):
  File "C:\Users\mkvet\.virtualenvs\backend-ZuzYmCFP\lib\site-packages\django\template\base.py", line 850, in _resolve_lookup
    (bit, current))  # missing attribute
django.template.base.VariableDoesNotExist: Failed lookup for key [name] in <URLResolver <module 'rest_framework.urls' from 'C:\\Users\\mkvet\\.virtualenvs\\backend-ZuzYmCFP\\lib\\site-packages\\rest_framework\\urls.py'> (rest_framework:rest_framework) 'api-auth/'>
Exception while resolving variable 'name' in template 'unknown'.
Traceback (most recent call last):
  File "C:\Users\mkvet\.virtualenvs\backend-ZuzYmCFP\lib\site-packages\django\core\handlers\exception.py", line 34, in inner
    response = get_response(request)
  File "C:\Users\mkvet\.virtualenvs\backend-ZuzYmCFP\lib\site-packages\django\core\handlers\base.py", line 111, in _get_response
    resolver_match = resolver.resolve(request.path_info)
  File "C:\Users\mkvet\.virtualenvs\backend-ZuzYmCFP\lib\site-packages\django\urls\resolvers.py", line 520, in resolve
    raise Resolver404({'tried': tried, 'path': new_path})
django.urls.exceptions.Resolver404: {'tried': [[<URLResolver <module 'shop.urls' from 'C:\\Users\\mkvet\\Documents\\Uni\\7_Semester\\WebDevSpecial\\puppy-webshop\\backend\\shop\\urls.py'> (None:None) 'shop/'>], [<URLResolver <URLPattern list> (admin:admin) 'admin/'>], [<URLPattern 'token-auth/'>], [<URLResolver <module 'rest_framework.urls' from 'C:\\Users\\mkvet\\.virtualenvs\\backend-ZuzYmCFP\\lib\\site-packages\\rest_framework\\urls.py'> (rest_framework:rest_framework) 'api-auth/'>], [<URLResolver <module 'letsencrypt.urls' from 'C:\\Users\\mkvet\\.virtualenvs\\backend-ZuzYmCFP\\lib\\site-packages\\letsencrypt\\urls.py'> (None:None) '\.well-known/'>]], 'path': 'favicon.ico'}

During handling of the above exception, another exception occurred:

Traceback (most recent call last):
  File "C:\Users\mkvet\.virtualenvs\backend-ZuzYmCFP\lib\site-packages\django\template\base.py", line 829, in _resolve_lookup
    current = current[bit]
TypeError: 'URLResolver' object is not subscriptable

During handling of the above exception, another exception occurred:

Traceback (most recent call last):
  File "C:\Users\mkvet\.virtualenvs\backend-ZuzYmCFP\lib\site-packages\django\template\base.py", line 837, in _resolve_lookup
    current = getattr(current, bit)
AttributeError: 'URLResolver' object has no attribute 'name'

During handling of the above exception, another exception occurred:

Traceback (most recent call last):
  File "C:\Users\mkvet\.virtualenvs\backend-ZuzYmCFP\lib\site-packages\django\template\base.py", line 843, in _resolve_lookup
    current = current[int(bit)]
ValueError: invalid literal for int() with base 10: 'name'

During handling of the above exception, another exception occurred:

Traceback (most recent call last):
  File "C:\Users\mkvet\.virtualenvs\backend-ZuzYmCFP\lib\site-packages\django\template\base.py", line 850, in _resolve_lookup
    (bit, current))  # missing attribute
django.template.base.VariableDoesNotExist: Failed lookup for key [name] in <URLResolver <module 'letsencrypt.urls' from 'C:\\Users\\mkvet\\.virtualenvs\\backend-ZuzYmCFP\\lib\\site-packages\\letsencrypt\\urls.py'> (None:None) '\.well-known/'>
Not Found: /favicon.ico
"GET /favicon.ico HTTP/1.1" 404 2412
(0.122) 
            SELECT c.relname, c.relkind
            FROM pg_catalog.pg_class c
            LEFT JOIN pg_catalog.pg_namespace n ON n.oid = c.relnamespace
            WHERE c.relkind IN ('r', 'v')
                AND n.nspname NOT IN ('pg_catalog', 'pg_toast')
                AND pg_catalog.pg_table_is_visible(c.oid); args=None
(0.026) SELECT "django_migrations"."app", "django_migrations"."name" FROM "django_migrations"; args=()
(0.006) 
            SELECT c.relname, c.relkind
            FROM pg_catalog.pg_class c
            LEFT JOIN pg_catalog.pg_namespace n ON n.oid = c.relnamespace
            WHERE c.relkind IN ('r', 'v')
                AND n.nspname NOT IN ('pg_catalog', 'pg_toast')
                AND pg_catalog.pg_table_is_visible(c.oid); args=None
(0.002) SELECT "django_migrations"."app", "django_migrations"."name" FROM "django_migrations"; args=()
(0.003) 
            SELECT c.relname, c.relkind
            FROM pg_catalog.pg_class c
            LEFT JOIN pg_catalog.pg_namespace n ON n.oid = c.relnamespace
            WHERE c.relkind IN ('r', 'v')
                AND n.nspname NOT IN ('pg_catalog', 'pg_toast')
                AND pg_catalog.pg_table_is_visible(c.oid); args=None
(0.001) SELECT "django_migrations"."app", "django_migrations"."name" FROM "django_migrations"; args=()
(0.001) 
            SELECT c.relname, c.relkind
            FROM pg_catalog.pg_class c
            LEFT JOIN pg_catalog.pg_namespace n ON n.oid = c.relnamespace
            WHERE c.relkind IN ('r', 'v')
                AND n.nspname NOT IN ('pg_catalog', 'pg_toast')
                AND pg_catalog.pg_table_is_visible(c.oid); args=None
(0.001) 
            SELECT c.relname, c.relkind
            FROM pg_catalog.pg_class c
            LEFT JOIN pg_catalog.pg_namespace n ON n.oid = c.relnamespace
            WHERE c.relkind IN ('r', 'v')
                AND n.nspname NOT IN ('pg_catalog', 'pg_toast')
                AND pg_catalog.pg_table_is_visible(c.oid); args=None
(0.001) SELECT "django_migrations"."app", "django_migrations"."name" FROM "django_migrations"; args=()
(0.054) SELECT "django_content_type"."id", "django_content_type"."app_label", "django_content_type"."model" FROM "django_content_type" WHERE ("django_content_type"."app_label" = 'shop' AND "django_content_type"."model" = 'address'); args=('shop', 'address')
(0.001) SELECT "django_content_type"."id", "django_content_type"."app_label", "django_content_type"."model" FROM "django_content_type" WHERE ("django_content_type"."app_label" = 'shop' AND "django_content_type"."model" = 'order'); args=('shop', 'order')
(0.000) SELECT "django_content_type"."id", "django_content_type"."app_label", "django_content_type"."model" FROM "django_content_type" WHERE ("django_content_type"."app_label" = 'shop' AND "django_content_type"."model" = 'puppy'); args=('shop', 'puppy')
(0.001) SELECT "django_content_type"."id", "django_content_type"."app_label", "django_content_type"."model" FROM "django_content_type" WHERE ("django_content_type"."app_label" = 'shop' AND "django_content_type"."model" = 'puppyorder'); args=('shop', 'puppyorder')
(0.053) SELECT "auth_permission"."content_type_id", "auth_permission"."codename" FROM "auth_permission" INNER JOIN "django_content_type" ON ("auth_permission"."content_type_id" = "django_content_type"."id") WHERE "auth_permission"."content_type_id" IN (9, 2, 10, 1) ORDER BY "django_content_type"."app_label" ASC, "django_content_type"."model" ASC, "auth_permission"."codename" ASC; args=(9, 2, 10, 1)
(0.001) SELECT "django_content_type"."id", "django_content_type"."app_label", "django_content_type"."model" FROM "django_content_type" WHERE "django_content_type"."app_label" = 'shop'; args=('shop',)
(0.001) SELECT "django_content_type"."id", "django_content_type"."app_label", "django_content_type"."model" FROM "django_content_type" WHERE ("django_content_type"."app_label" = 'admin' AND "django_content_type"."model" = 'logentry'); args=('admin', 'logentry')
(0.002) SELECT "auth_permission"."content_type_id", "auth_permission"."codename" FROM "auth_permission" INNER JOIN "django_content_type" ON ("auth_permission"."content_type_id" = "django_content_type"."id") WHERE "auth_permission"."content_type_id" IN (3) ORDER BY "django_content_type"."app_label" ASC, "django_content_type"."model" ASC, "auth_permission"."codename" ASC; args=(3,)
(0.001) SELECT "django_content_type"."id", "django_content_type"."app_label", "django_content_type"."model" FROM "django_content_type" WHERE "django_content_type"."app_label" = 'admin'; args=('admin',)
(0.001) SELECT "django_content_type"."id", "django_content_type"."app_label", "django_content_type"."model" FROM "django_content_type" WHERE ("django_content_type"."app_label" = 'auth' AND "django_content_type"."model" = 'permission'); args=('auth', 'permission')
(0.001) SELECT "django_content_type"."id", "django_content_type"."app_label", "django_content_type"."model" FROM "django_content_type" WHERE ("django_content_type"."app_label" = 'auth' AND "django_content_type"."model" = 'group'); args=('auth', 'group')
(0.001) SELECT "django_content_type"."id", "django_content_type"."app_label", "django_content_type"."model" FROM "django_content_type" WHERE ("django_content_type"."app_label" = 'auth' AND "django_content_type"."model" = 'user'); args=('auth', 'user')
(0.001) SELECT "auth_permission"."content_type_id", "auth_permission"."codename" FROM "auth_permission" INNER JOIN "django_content_type" ON ("auth_permission"."content_type_id" = "django_content_type"."id") WHERE "auth_permission"."content_type_id" IN (4, 5, 6) ORDER BY "django_content_type"."app_label" ASC, "django_content_type"."model" ASC, "auth_permission"."codename" ASC; args=(4, 5, 6)
(0.001) SELECT "django_content_type"."id", "django_content_type"."app_label", "django_content_type"."model" FROM "django_content_type" WHERE "django_content_type"."app_label" = 'auth'; args=('auth',)
(0.001) SELECT "django_content_type"."id", "django_content_type"."app_label", "django_content_type"."model" FROM "django_content_type" WHERE ("django_content_type"."app_label" = 'contenttypes' AND "django_content_type"."model" = 'contenttype'); args=('contenttypes', 'contenttype')
(0.001) SELECT "auth_permission"."content_type_id", "auth_permission"."codename" FROM "auth_permission" INNER JOIN "django_content_type" ON ("auth_permission"."content_type_id" = "django_content_type"."id") WHERE "auth_permission"."content_type_id" IN (7) ORDER BY "django_content_type"."app_label" ASC, "django_content_type"."model" ASC, "auth_permission"."codename" ASC; args=(7,)
(0.000) SELECT "django_content_type"."id", "django_content_type"."app_label", "django_content_type"."model" FROM "django_content_type" WHERE "django_content_type"."app_label" = 'contenttypes'; args=('contenttypes',)
(0.001) SELECT "django_content_type"."id", "django_content_type"."app_label", "django_content_type"."model" FROM "django_content_type" WHERE ("django_content_type"."app_label" = 'sessions' AND "django_content_type"."model" = 'session'); args=('sessions', 'session')
(0.001) SELECT "auth_permission"."content_type_id", "auth_permission"."codename" FROM "auth_permission" INNER JOIN "django_content_type" ON ("auth_permission"."content_type_id" = "django_content_type"."id") WHERE "auth_permission"."content_type_id" IN (8) ORDER BY "django_content_type"."app_label" ASC, "django_content_type"."model" ASC, "auth_permission"."codename" ASC; args=(8,)
(0.001) SELECT "django_content_type"."id", "django_content_type"."app_label", "django_content_type"."model" FROM "django_content_type" WHERE "django_content_type"."app_label" = 'sessions'; args=('sessions',)
(0.001) SELECT "django_content_type"."id", "django_content_type"."app_label", "django_content_type"."model" FROM "django_content_type" WHERE "django_content_type"."app_label" = 'corsheaders'; args=('corsheaders',)
(0.001) SELECT "django_content_type"."id", "django_content_type"."app_label", "django_content_type"."model" FROM "django_content_type" WHERE ("django_content_type"."app_label" = 'letsencrypt' AND "django_content_type"."model" = 'acmechallenge'); args=('letsencrypt', 'acmechallenge')
(0.001) SELECT "auth_permission"."content_type_id", "auth_permission"."codename" FROM "auth_permission" INNER JOIN "django_content_type" ON ("auth_permission"."content_type_id" = "django_content_type"."id") WHERE "auth_permission"."content_type_id" IN (11) ORDER BY "django_content_type"."app_label" ASC, "django_content_type"."model" ASC, "auth_permission"."codename" ASC; args=(11,)
(0.002) SELECT "django_content_type"."id", "django_content_type"."app_label", "django_content_type"."model" FROM "django_content_type" WHERE "django_content_type"."app_label" = 'letsencrypt'; args=('letsencrypt',)
Exception while resolving variable 'name' in template 'unknown'.
Traceback (most recent call last):
  File "C:\Users\Maxqu\Anaconda3\envs\puppy-webshop\lib\site-packages\django\core\handlers\exception.py", line 34, in inner
    response = get_response(request)
  File "C:\Users\Maxqu\Anaconda3\envs\puppy-webshop\lib\site-packages\django\core\handlers\base.py", line 111, in _get_response
    resolver_match = resolver.resolve(request.path_info)
  File "C:\Users\Maxqu\Anaconda3\envs\puppy-webshop\lib\site-packages\django\urls\resolvers.py", line 520, in resolve
    raise Resolver404({'tried': tried, 'path': new_path})
django.urls.exceptions.Resolver404: {'tried': [[<URLResolver <module 'shop.urls' from 'C:\\Users\\Maxqu\\PycharmProjects\\puppy-webshop\\backend\\shop\\urls.py'> (None:None) 'shop/'>], [<URLResolver <URLPattern list> (admin:admin) 'admin/'>], [<URLPattern 'token-auth/'>], [<URLResolver <module 'rest_framework.urls' from 'C:\\Users\\Maxqu\\Anaconda3\\envs\\puppy-webshop\\lib\\site-packages\\rest_framework\\urls.py'> (rest_framework:rest_framework) 'api-auth/'>], [<URLResolver <module 'letsencrypt.urls' from 'C:\\Users\\Maxqu\\Anaconda3\\envs\\puppy-webshop\\lib\\site-packages\\letsencrypt\\urls.py'> (None:None) '\.well-known/'>]], 'path': ''}

During handling of the above exception, another exception occurred:

Traceback (most recent call last):
  File "C:\Users\Maxqu\Anaconda3\envs\puppy-webshop\lib\site-packages\django\template\base.py", line 829, in _resolve_lookup
    current = current[bit]
TypeError: 'URLResolver' object is not subscriptable

During handling of the above exception, another exception occurred:

Traceback (most recent call last):
  File "C:\Users\Maxqu\Anaconda3\envs\puppy-webshop\lib\site-packages\django\template\base.py", line 837, in _resolve_lookup
    current = getattr(current, bit)
AttributeError: 'URLResolver' object has no attribute 'name'

During handling of the above exception, another exception occurred:

Traceback (most recent call last):
  File "C:\Users\Maxqu\Anaconda3\envs\puppy-webshop\lib\site-packages\django\template\base.py", line 843, in _resolve_lookup
    current = current[int(bit)]
ValueError: invalid literal for int() with base 10: 'name'

During handling of the above exception, another exception occurred:

Traceback (most recent call last):
  File "C:\Users\Maxqu\Anaconda3\envs\puppy-webshop\lib\site-packages\django\template\base.py", line 850, in _resolve_lookup
    (bit, current))  # missing attribute
django.template.base.VariableDoesNotExist: Failed lookup for key [name] in <URLResolver <module 'shop.urls' from 'C:\\Users\\Maxqu\\PycharmProjects\\puppy-webshop\\backend\\shop\\urls.py'> (None:None) 'shop/'>
Exception while resolving variable 'name' in template 'unknown'.
Traceback (most recent call last):
  File "C:\Users\Maxqu\Anaconda3\envs\puppy-webshop\lib\site-packages\django\core\handlers\exception.py", line 34, in inner
    response = get_response(request)
  File "C:\Users\Maxqu\Anaconda3\envs\puppy-webshop\lib\site-packages\django\core\handlers\base.py", line 111, in _get_response
    resolver_match = resolver.resolve(request.path_info)
  File "C:\Users\Maxqu\Anaconda3\envs\puppy-webshop\lib\site-packages\django\urls\resolvers.py", line 520, in resolve
    raise Resolver404({'tried': tried, 'path': new_path})
django.urls.exceptions.Resolver404: {'tried': [[<URLResolver <module 'shop.urls' from 'C:\\Users\\Maxqu\\PycharmProjects\\puppy-webshop\\backend\\shop\\urls.py'> (None:None) 'shop/'>], [<URLResolver <URLPattern list> (admin:admin) 'admin/'>], [<URLPattern 'token-auth/'>], [<URLResolver <module 'rest_framework.urls' from 'C:\\Users\\Maxqu\\Anaconda3\\envs\\puppy-webshop\\lib\\site-packages\\rest_framework\\urls.py'> (rest_framework:rest_framework) 'api-auth/'>], [<URLResolver <module 'letsencrypt.urls' from 'C:\\Users\\Maxqu\\Anaconda3\\envs\\puppy-webshop\\lib\\site-packages\\letsencrypt\\urls.py'> (None:None) '\.well-known/'>]], 'path': ''}

During handling of the above exception, another exception occurred:

Traceback (most recent call last):
  File "C:\Users\Maxqu\Anaconda3\envs\puppy-webshop\lib\site-packages\django\template\base.py", line 829, in _resolve_lookup
    current = current[bit]
TypeError: 'URLResolver' object is not subscriptable

During handling of the above exception, another exception occurred:

Traceback (most recent call last):
  File "C:\Users\Maxqu\Anaconda3\envs\puppy-webshop\lib\site-packages\django\template\base.py", line 837, in _resolve_lookup
    current = getattr(current, bit)
AttributeError: 'URLResolver' object has no attribute 'name'

During handling of the above exception, another exception occurred:

Traceback (most recent call last):
  File "C:\Users\Maxqu\Anaconda3\envs\puppy-webshop\lib\site-packages\django\template\base.py", line 843, in _resolve_lookup
    current = current[int(bit)]
ValueError: invalid literal for int() with base 10: 'name'

During handling of the above exception, another exception occurred:

Traceback (most recent call last):
  File "C:\Users\Maxqu\Anaconda3\envs\puppy-webshop\lib\site-packages\django\template\base.py", line 850, in _resolve_lookup
    (bit, current))  # missing attribute
django.template.base.VariableDoesNotExist: Failed lookup for key [name] in <URLResolver <URLPattern list> (admin:admin) 'admin/'>
Exception while resolving variable 'name' in template 'unknown'.
Traceback (most recent call last):
  File "C:\Users\Maxqu\Anaconda3\envs\puppy-webshop\lib\site-packages\django\core\handlers\exception.py", line 34, in inner
    response = get_response(request)
  File "C:\Users\Maxqu\Anaconda3\envs\puppy-webshop\lib\site-packages\django\core\handlers\base.py", line 111, in _get_response
    resolver_match = resolver.resolve(request.path_info)
  File "C:\Users\Maxqu\Anaconda3\envs\puppy-webshop\lib\site-packages\django\urls\resolvers.py", line 520, in resolve
    raise Resolver404({'tried': tried, 'path': new_path})
django.urls.exceptions.Resolver404: {'tried': [[<URLResolver <module 'shop.urls' from 'C:\\Users\\Maxqu\\PycharmProjects\\puppy-webshop\\backend\\shop\\urls.py'> (None:None) 'shop/'>], [<URLResolver <URLPattern list> (admin:admin) 'admin/'>], [<URLPattern 'token-auth/'>], [<URLResolver <module 'rest_framework.urls' from 'C:\\Users\\Maxqu\\Anaconda3\\envs\\puppy-webshop\\lib\\site-packages\\rest_framework\\urls.py'> (rest_framework:rest_framework) 'api-auth/'>], [<URLResolver <module 'letsencrypt.urls' from 'C:\\Users\\Maxqu\\Anaconda3\\envs\\puppy-webshop\\lib\\site-packages\\letsencrypt\\urls.py'> (None:None) '\.well-known/'>]], 'path': ''}

During handling of the above exception, another exception occurred:

Traceback (most recent call last):
  File "C:\Users\Maxqu\Anaconda3\envs\puppy-webshop\lib\site-packages\django\template\base.py", line 829, in _resolve_lookup
    current = current[bit]
TypeError: 'URLResolver' object is not subscriptable

During handling of the above exception, another exception occurred:

Traceback (most recent call last):
  File "C:\Users\Maxqu\Anaconda3\envs\puppy-webshop\lib\site-packages\django\template\base.py", line 837, in _resolve_lookup
    current = getattr(current, bit)
AttributeError: 'URLResolver' object has no attribute 'name'

During handling of the above exception, another exception occurred:

Traceback (most recent call last):
  File "C:\Users\Maxqu\Anaconda3\envs\puppy-webshop\lib\site-packages\django\template\base.py", line 843, in _resolve_lookup
    current = current[int(bit)]
ValueError: invalid literal for int() with base 10: 'name'

During handling of the above exception, another exception occurred:

Traceback (most recent call last):
  File "C:\Users\Maxqu\Anaconda3\envs\puppy-webshop\lib\site-packages\django\template\base.py", line 850, in _resolve_lookup
    (bit, current))  # missing attribute
django.template.base.VariableDoesNotExist: Failed lookup for key [name] in <URLResolver <module 'rest_framework.urls' from 'C:\\Users\\Maxqu\\Anaconda3\\envs\\puppy-webshop\\lib\\site-packages\\rest_framework\\urls.py'> (rest_framework:rest_framework) 'api-auth/'>
Exception while resolving variable 'name' in template 'unknown'.
Traceback (most recent call last):
  File "C:\Users\Maxqu\Anaconda3\envs\puppy-webshop\lib\site-packages\django\core\handlers\exception.py", line 34, in inner
    response = get_response(request)
  File "C:\Users\Maxqu\Anaconda3\envs\puppy-webshop\lib\site-packages\django\core\handlers\base.py", line 111, in _get_response
    resolver_match = resolver.resolve(request.path_info)
  File "C:\Users\Maxqu\Anaconda3\envs\puppy-webshop\lib\site-packages\django\urls\resolvers.py", line 520, in resolve
    raise Resolver404({'tried': tried, 'path': new_path})
django.urls.exceptions.Resolver404: {'tried': [[<URLResolver <module 'shop.urls' from 'C:\\Users\\Maxqu\\PycharmProjects\\puppy-webshop\\backend\\shop\\urls.py'> (None:None) 'shop/'>], [<URLResolver <URLPattern list> (admin:admin) 'admin/'>], [<URLPattern 'token-auth/'>], [<URLResolver <module 'rest_framework.urls' from 'C:\\Users\\Maxqu\\Anaconda3\\envs\\puppy-webshop\\lib\\site-packages\\rest_framework\\urls.py'> (rest_framework:rest_framework) 'api-auth/'>], [<URLResolver <module 'letsencrypt.urls' from 'C:\\Users\\Maxqu\\Anaconda3\\envs\\puppy-webshop\\lib\\site-packages\\letsencrypt\\urls.py'> (None:None) '\.well-known/'>]], 'path': ''}

During handling of the above exception, another exception occurred:

Traceback (most recent call last):
  File "C:\Users\Maxqu\Anaconda3\envs\puppy-webshop\lib\site-packages\django\template\base.py", line 829, in _resolve_lookup
    current = current[bit]
TypeError: 'URLResolver' object is not subscriptable

During handling of the above exception, another exception occurred:

Traceback (most recent call last):
  File "C:\Users\Maxqu\Anaconda3\envs\puppy-webshop\lib\site-packages\django\template\base.py", line 837, in _resolve_lookup
    current = getattr(current, bit)
AttributeError: 'URLResolver' object has no attribute 'name'

During handling of the above exception, another exception occurred:

Traceback (most recent call last):
  File "C:\Users\Maxqu\Anaconda3\envs\puppy-webshop\lib\site-packages\django\template\base.py", line 843, in _resolve_lookup
    current = current[int(bit)]
ValueError: invalid literal for int() with base 10: 'name'

During handling of the above exception, another exception occurred:

Traceback (most recent call last):
  File "C:\Users\Maxqu\Anaconda3\envs\puppy-webshop\lib\site-packages\django\template\base.py", line 850, in _resolve_lookup
    (bit, current))  # missing attribute
django.template.base.VariableDoesNotExist: Failed lookup for key [name] in <URLResolver <module 'letsencrypt.urls' from 'C:\\Users\\Maxqu\\Anaconda3\\envs\\puppy-webshop\\lib\\site-packages\\letsencrypt\\urls.py'> (None:None) '\.well-known/'>
Not Found: /
"GET / HTTP/1.1" 404 2361
Exception while resolving variable 'name' in template 'unknown'.
Traceback (most recent call last):
  File "C:\Users\Maxqu\Anaconda3\envs\puppy-webshop\lib\site-packages\django\core\handlers\exception.py", line 34, in inner
    response = get_response(request)
  File "C:\Users\Maxqu\Anaconda3\envs\puppy-webshop\lib\site-packages\django\core\handlers\base.py", line 111, in _get_response
    resolver_match = resolver.resolve(request.path_info)
  File "C:\Users\Maxqu\Anaconda3\envs\puppy-webshop\lib\site-packages\django\urls\resolvers.py", line 520, in resolve
    raise Resolver404({'tried': tried, 'path': new_path})
django.urls.exceptions.Resolver404: {'tried': [[<URLResolver <module 'shop.urls' from 'C:\\Users\\Maxqu\\PycharmProjects\\puppy-webshop\\backend\\shop\\urls.py'> (None:None) 'shop/'>], [<URLResolver <URLPattern list> (admin:admin) 'admin/'>], [<URLPattern 'token-auth/'>], [<URLResolver <module 'rest_framework.urls' from 'C:\\Users\\Maxqu\\Anaconda3\\envs\\puppy-webshop\\lib\\site-packages\\rest_framework\\urls.py'> (rest_framework:rest_framework) 'api-auth/'>], [<URLResolver <module 'letsencrypt.urls' from 'C:\\Users\\Maxqu\\Anaconda3\\envs\\puppy-webshop\\lib\\site-packages\\letsencrypt\\urls.py'> (None:None) '\.well-known/'>]], 'path': '.well-known/'}

During handling of the above exception, another exception occurred:

Traceback (most recent call last):
  File "C:\Users\Maxqu\Anaconda3\envs\puppy-webshop\lib\site-packages\django\template\base.py", line 829, in _resolve_lookup
    current = current[bit]
TypeError: 'URLResolver' object is not subscriptable

During handling of the above exception, another exception occurred:

Traceback (most recent call last):
  File "C:\Users\Maxqu\Anaconda3\envs\puppy-webshop\lib\site-packages\django\template\base.py", line 837, in _resolve_lookup
    current = getattr(current, bit)
AttributeError: 'URLResolver' object has no attribute 'name'

During handling of the above exception, another exception occurred:

Traceback (most recent call last):
  File "C:\Users\Maxqu\Anaconda3\envs\puppy-webshop\lib\site-packages\django\template\base.py", line 843, in _resolve_lookup
    current = current[int(bit)]
ValueError: invalid literal for int() with base 10: 'name'

During handling of the above exception, another exception occurred:

Traceback (most recent call last):
  File "C:\Users\Maxqu\Anaconda3\envs\puppy-webshop\lib\site-packages\django\template\base.py", line 850, in _resolve_lookup
    (bit, current))  # missing attribute
django.template.base.VariableDoesNotExist: Failed lookup for key [name] in <URLResolver <module 'shop.urls' from 'C:\\Users\\Maxqu\\PycharmProjects\\puppy-webshop\\backend\\shop\\urls.py'> (None:None) 'shop/'>
Exception while resolving variable 'name' in template 'unknown'.
Traceback (most recent call last):
  File "C:\Users\Maxqu\Anaconda3\envs\puppy-webshop\lib\site-packages\django\core\handlers\exception.py", line 34, in inner
    response = get_response(request)
  File "C:\Users\Maxqu\Anaconda3\envs\puppy-webshop\lib\site-packages\django\core\handlers\base.py", line 111, in _get_response
    resolver_match = resolver.resolve(request.path_info)
  File "C:\Users\Maxqu\Anaconda3\envs\puppy-webshop\lib\site-packages\django\urls\resolvers.py", line 520, in resolve
    raise Resolver404({'tried': tried, 'path': new_path})
django.urls.exceptions.Resolver404: {'tried': [[<URLResolver <module 'shop.urls' from 'C:\\Users\\Maxqu\\PycharmProjects\\puppy-webshop\\backend\\shop\\urls.py'> (None:None) 'shop/'>], [<URLResolver <URLPattern list> (admin:admin) 'admin/'>], [<URLPattern 'token-auth/'>], [<URLResolver <module 'rest_framework.urls' from 'C:\\Users\\Maxqu\\Anaconda3\\envs\\puppy-webshop\\lib\\site-packages\\rest_framework\\urls.py'> (rest_framework:rest_framework) 'api-auth/'>], [<URLResolver <module 'letsencrypt.urls' from 'C:\\Users\\Maxqu\\Anaconda3\\envs\\puppy-webshop\\lib\\site-packages\\letsencrypt\\urls.py'> (None:None) '\.well-known/'>]], 'path': '.well-known/'}

During handling of the above exception, another exception occurred:

Traceback (most recent call last):
  File "C:\Users\Maxqu\Anaconda3\envs\puppy-webshop\lib\site-packages\django\template\base.py", line 829, in _resolve_lookup
    current = current[bit]
TypeError: 'URLResolver' object is not subscriptable

During handling of the above exception, another exception occurred:

Traceback (most recent call last):
  File "C:\Users\Maxqu\Anaconda3\envs\puppy-webshop\lib\site-packages\django\template\base.py", line 837, in _resolve_lookup
    current = getattr(current, bit)
AttributeError: 'URLResolver' object has no attribute 'name'

During handling of the above exception, another exception occurred:

Traceback (most recent call last):
  File "C:\Users\Maxqu\Anaconda3\envs\puppy-webshop\lib\site-packages\django\template\base.py", line 843, in _resolve_lookup
    current = current[int(bit)]
ValueError: invalid literal for int() with base 10: 'name'

During handling of the above exception, another exception occurred:

Traceback (most recent call last):
  File "C:\Users\Maxqu\Anaconda3\envs\puppy-webshop\lib\site-packages\django\template\base.py", line 850, in _resolve_lookup
    (bit, current))  # missing attribute
django.template.base.VariableDoesNotExist: Failed lookup for key [name] in <URLResolver <URLPattern list> (admin:admin) 'admin/'>
Exception while resolving variable 'name' in template 'unknown'.
Traceback (most recent call last):
  File "C:\Users\Maxqu\Anaconda3\envs\puppy-webshop\lib\site-packages\django\core\handlers\exception.py", line 34, in inner
    response = get_response(request)
  File "C:\Users\Maxqu\Anaconda3\envs\puppy-webshop\lib\site-packages\django\core\handlers\base.py", line 111, in _get_response
    resolver_match = resolver.resolve(request.path_info)
  File "C:\Users\Maxqu\Anaconda3\envs\puppy-webshop\lib\site-packages\django\urls\resolvers.py", line 520, in resolve
    raise Resolver404({'tried': tried, 'path': new_path})
django.urls.exceptions.Resolver404: {'tried': [[<URLResolver <module 'shop.urls' from 'C:\\Users\\Maxqu\\PycharmProjects\\puppy-webshop\\backend\\shop\\urls.py'> (None:None) 'shop/'>], [<URLResolver <URLPattern list> (admin:admin) 'admin/'>], [<URLPattern 'token-auth/'>], [<URLResolver <module 'rest_framework.urls' from 'C:\\Users\\Maxqu\\Anaconda3\\envs\\puppy-webshop\\lib\\site-packages\\rest_framework\\urls.py'> (rest_framework:rest_framework) 'api-auth/'>], [<URLResolver <module 'letsencrypt.urls' from 'C:\\Users\\Maxqu\\Anaconda3\\envs\\puppy-webshop\\lib\\site-packages\\letsencrypt\\urls.py'> (None:None) '\.well-known/'>]], 'path': '.well-known/'}

During handling of the above exception, another exception occurred:

Traceback (most recent call last):
  File "C:\Users\Maxqu\Anaconda3\envs\puppy-webshop\lib\site-packages\django\template\base.py", line 829, in _resolve_lookup
    current = current[bit]
TypeError: 'URLResolver' object is not subscriptable

During handling of the above exception, another exception occurred:

Traceback (most recent call last):
  File "C:\Users\Maxqu\Anaconda3\envs\puppy-webshop\lib\site-packages\django\template\base.py", line 837, in _resolve_lookup
    current = getattr(current, bit)
AttributeError: 'URLResolver' object has no attribute 'name'

During handling of the above exception, another exception occurred:

Traceback (most recent call last):
  File "C:\Users\Maxqu\Anaconda3\envs\puppy-webshop\lib\site-packages\django\template\base.py", line 843, in _resolve_lookup
    current = current[int(bit)]
ValueError: invalid literal for int() with base 10: 'name'

During handling of the above exception, another exception occurred:

Traceback (most recent call last):
  File "C:\Users\Maxqu\Anaconda3\envs\puppy-webshop\lib\site-packages\django\template\base.py", line 850, in _resolve_lookup
    (bit, current))  # missing attribute
django.template.base.VariableDoesNotExist: Failed lookup for key [name] in <URLResolver <module 'rest_framework.urls' from 'C:\\Users\\Maxqu\\Anaconda3\\envs\\puppy-webshop\\lib\\site-packages\\rest_framework\\urls.py'> (rest_framework:rest_framework) 'api-auth/'>
Exception while resolving variable 'name' in template 'unknown'.
Traceback (most recent call last):
  File "C:\Users\Maxqu\Anaconda3\envs\puppy-webshop\lib\site-packages\django\core\handlers\exception.py", line 34, in inner
    response = get_response(request)
  File "C:\Users\Maxqu\Anaconda3\envs\puppy-webshop\lib\site-packages\django\core\handlers\base.py", line 111, in _get_response
    resolver_match = resolver.resolve(request.path_info)
  File "C:\Users\Maxqu\Anaconda3\envs\puppy-webshop\lib\site-packages\django\urls\resolvers.py", line 520, in resolve
    raise Resolver404({'tried': tried, 'path': new_path})
django.urls.exceptions.Resolver404: {'tried': [[<URLResolver <module 'shop.urls' from 'C:\\Users\\Maxqu\\PycharmProjects\\puppy-webshop\\backend\\shop\\urls.py'> (None:None) 'shop/'>], [<URLResolver <URLPattern list> (admin:admin) 'admin/'>], [<URLPattern 'token-auth/'>], [<URLResolver <module 'rest_framework.urls' from 'C:\\Users\\Maxqu\\Anaconda3\\envs\\puppy-webshop\\lib\\site-packages\\rest_framework\\urls.py'> (rest_framework:rest_framework) 'api-auth/'>], [<URLResolver <module 'letsencrypt.urls' from 'C:\\Users\\Maxqu\\Anaconda3\\envs\\puppy-webshop\\lib\\site-packages\\letsencrypt\\urls.py'> (None:None) '\.well-known/'>]], 'path': '.well-known/'}

During handling of the above exception, another exception occurred:

Traceback (most recent call last):
  File "C:\Users\Maxqu\Anaconda3\envs\puppy-webshop\lib\site-packages\django\template\base.py", line 829, in _resolve_lookup
    current = current[bit]
TypeError: 'URLResolver' object is not subscriptable

During handling of the above exception, another exception occurred:

Traceback (most recent call last):
  File "C:\Users\Maxqu\Anaconda3\envs\puppy-webshop\lib\site-packages\django\template\base.py", line 837, in _resolve_lookup
    current = getattr(current, bit)
AttributeError: 'URLResolver' object has no attribute 'name'

During handling of the above exception, another exception occurred:

Traceback (most recent call last):
  File "C:\Users\Maxqu\Anaconda3\envs\puppy-webshop\lib\site-packages\django\template\base.py", line 843, in _resolve_lookup
    current = current[int(bit)]
ValueError: invalid literal for int() with base 10: 'name'

During handling of the above exception, another exception occurred:

Traceback (most recent call last):
  File "C:\Users\Maxqu\Anaconda3\envs\puppy-webshop\lib\site-packages\django\template\base.py", line 850, in _resolve_lookup
    (bit, current))  # missing attribute
django.template.base.VariableDoesNotExist: Failed lookup for key [name] in <URLResolver <module 'letsencrypt.urls' from 'C:\\Users\\Maxqu\\Anaconda3\\envs\\puppy-webshop\\lib\\site-packages\\letsencrypt\\urls.py'> (None:None) '\.well-known/'>
Not Found: /.well-known/
"GET /.well-known/ HTTP/1.1" 404 2415
Exception while resolving variable 'name' in template 'unknown'.
Traceback (most recent call last):
  File "C:\Users\Maxqu\Anaconda3\envs\puppy-webshop\lib\site-packages\django\core\handlers\exception.py", line 34, in inner
    response = get_response(request)
  File "C:\Users\Maxqu\Anaconda3\envs\puppy-webshop\lib\site-packages\django\core\handlers\base.py", line 111, in _get_response
    resolver_match = resolver.resolve(request.path_info)
  File "C:\Users\Maxqu\Anaconda3\envs\puppy-webshop\lib\site-packages\django\urls\resolvers.py", line 520, in resolve
    raise Resolver404({'tried': tried, 'path': new_path})
django.urls.exceptions.Resolver404: {'tried': [[<URLResolver <module 'shop.urls' from 'C:\\Users\\Maxqu\\PycharmProjects\\puppy-webshop\\backend\\shop\\urls.py'> (None:None) 'shop/'>], [<URLResolver <URLPattern list> (admin:admin) 'admin/'>], [<URLPattern 'token-auth/'>], [<URLResolver <module 'rest_framework.urls' from 'C:\\Users\\Maxqu\\Anaconda3\\envs\\puppy-webshop\\lib\\site-packages\\rest_framework\\urls.py'> (rest_framework:rest_framework) 'api-auth/'>], [<URLResolver <module 'letsencrypt.urls' from 'C:\\Users\\Maxqu\\Anaconda3\\envs\\puppy-webshop\\lib\\site-packages\\letsencrypt\\urls.py'> (None:None) '\.well-known/'>]], 'path': '.well-known/'}

During handling of the above exception, another exception occurred:

Traceback (most recent call last):
  File "C:\Users\Maxqu\Anaconda3\envs\puppy-webshop\lib\site-packages\django\template\base.py", line 829, in _resolve_lookup
    current = current[bit]
TypeError: 'URLResolver' object is not subscriptable

During handling of the above exception, another exception occurred:

Traceback (most recent call last):
  File "C:\Users\Maxqu\Anaconda3\envs\puppy-webshop\lib\site-packages\django\template\base.py", line 837, in _resolve_lookup
    current = getattr(current, bit)
AttributeError: 'URLResolver' object has no attribute 'name'

During handling of the above exception, another exception occurred:

Traceback (most recent call last):
  File "C:\Users\Maxqu\Anaconda3\envs\puppy-webshop\lib\site-packages\django\template\base.py", line 843, in _resolve_lookup
    current = current[int(bit)]
ValueError: invalid literal for int() with base 10: 'name'

During handling of the above exception, another exception occurred:

Traceback (most recent call last):
  File "C:\Users\Maxqu\Anaconda3\envs\puppy-webshop\lib\site-packages\django\template\base.py", line 850, in _resolve_lookup
    (bit, current))  # missing attribute
django.template.base.VariableDoesNotExist: Failed lookup for key [name] in <URLResolver <module 'shop.urls' from 'C:\\Users\\Maxqu\\PycharmProjects\\puppy-webshop\\backend\\shop\\urls.py'> (None:None) 'shop/'>
Exception while resolving variable 'name' in template 'unknown'.
Traceback (most recent call last):
  File "C:\Users\Maxqu\Anaconda3\envs\puppy-webshop\lib\site-packages\django\core\handlers\exception.py", line 34, in inner
    response = get_response(request)
  File "C:\Users\Maxqu\Anaconda3\envs\puppy-webshop\lib\site-packages\django\core\handlers\base.py", line 111, in _get_response
    resolver_match = resolver.resolve(request.path_info)
  File "C:\Users\Maxqu\Anaconda3\envs\puppy-webshop\lib\site-packages\django\urls\resolvers.py", line 520, in resolve
    raise Resolver404({'tried': tried, 'path': new_path})
django.urls.exceptions.Resolver404: {'tried': [[<URLResolver <module 'shop.urls' from 'C:\\Users\\Maxqu\\PycharmProjects\\puppy-webshop\\backend\\shop\\urls.py'> (None:None) 'shop/'>], [<URLResolver <URLPattern list> (admin:admin) 'admin/'>], [<URLPattern 'token-auth/'>], [<URLResolver <module 'rest_framework.urls' from 'C:\\Users\\Maxqu\\Anaconda3\\envs\\puppy-webshop\\lib\\site-packages\\rest_framework\\urls.py'> (rest_framework:rest_framework) 'api-auth/'>], [<URLResolver <module 'letsencrypt.urls' from 'C:\\Users\\Maxqu\\Anaconda3\\envs\\puppy-webshop\\lib\\site-packages\\letsencrypt\\urls.py'> (None:None) '\.well-known/'>]], 'path': '.well-known/'}

During handling of the above exception, another exception occurred:

Traceback (most recent call last):
  File "C:\Users\Maxqu\Anaconda3\envs\puppy-webshop\lib\site-packages\django\template\base.py", line 829, in _resolve_lookup
    current = current[bit]
TypeError: 'URLResolver' object is not subscriptable

During handling of the above exception, another exception occurred:

Traceback (most recent call last):
  File "C:\Users\Maxqu\Anaconda3\envs\puppy-webshop\lib\site-packages\django\template\base.py", line 837, in _resolve_lookup
    current = getattr(current, bit)
AttributeError: 'URLResolver' object has no attribute 'name'

During handling of the above exception, another exception occurred:

Traceback (most recent call last):
  File "C:\Users\Maxqu\Anaconda3\envs\puppy-webshop\lib\site-packages\django\template\base.py", line 843, in _resolve_lookup
    current = current[int(bit)]
ValueError: invalid literal for int() with base 10: 'name'

During handling of the above exception, another exception occurred:

Traceback (most recent call last):
  File "C:\Users\Maxqu\Anaconda3\envs\puppy-webshop\lib\site-packages\django\template\base.py", line 850, in _resolve_lookup
    (bit, current))  # missing attribute
django.template.base.VariableDoesNotExist: Failed lookup for key [name] in <URLResolver <URLPattern list> (admin:admin) 'admin/'>
Exception while resolving variable 'name' in template 'unknown'.
Traceback (most recent call last):
  File "C:\Users\Maxqu\Anaconda3\envs\puppy-webshop\lib\site-packages\django\core\handlers\exception.py", line 34, in inner
    response = get_response(request)
  File "C:\Users\Maxqu\Anaconda3\envs\puppy-webshop\lib\site-packages\django\core\handlers\base.py", line 111, in _get_response
    resolver_match = resolver.resolve(request.path_info)
  File "C:\Users\Maxqu\Anaconda3\envs\puppy-webshop\lib\site-packages\django\urls\resolvers.py", line 520, in resolve
    raise Resolver404({'tried': tried, 'path': new_path})
django.urls.exceptions.Resolver404: {'tried': [[<URLResolver <module 'shop.urls' from 'C:\\Users\\Maxqu\\PycharmProjects\\puppy-webshop\\backend\\shop\\urls.py'> (None:None) 'shop/'>], [<URLResolver <URLPattern list> (admin:admin) 'admin/'>], [<URLPattern 'token-auth/'>], [<URLResolver <module 'rest_framework.urls' from 'C:\\Users\\Maxqu\\Anaconda3\\envs\\puppy-webshop\\lib\\site-packages\\rest_framework\\urls.py'> (rest_framework:rest_framework) 'api-auth/'>], [<URLResolver <module 'letsencrypt.urls' from 'C:\\Users\\Maxqu\\Anaconda3\\envs\\puppy-webshop\\lib\\site-packages\\letsencrypt\\urls.py'> (None:None) '\.well-known/'>]], 'path': '.well-known/'}

During handling of the above exception, another exception occurred:

Traceback (most recent call last):
  File "C:\Users\Maxqu\Anaconda3\envs\puppy-webshop\lib\site-packages\django\template\base.py", line 829, in _resolve_lookup
    current = current[bit]
TypeError: 'URLResolver' object is not subscriptable

During handling of the above exception, another exception occurred:

Traceback (most recent call last):
  File "C:\Users\Maxqu\Anaconda3\envs\puppy-webshop\lib\site-packages\django\template\base.py", line 837, in _resolve_lookup
    current = getattr(current, bit)
AttributeError: 'URLResolver' object has no attribute 'name'

During handling of the above exception, another exception occurred:

Traceback (most recent call last):
  File "C:\Users\Maxqu\Anaconda3\envs\puppy-webshop\lib\site-packages\django\template\base.py", line 843, in _resolve_lookup
    current = current[int(bit)]
ValueError: invalid literal for int() with base 10: 'name'

During handling of the above exception, another exception occurred:

Traceback (most recent call last):
  File "C:\Users\Maxqu\Anaconda3\envs\puppy-webshop\lib\site-packages\django\template\base.py", line 850, in _resolve_lookup
    (bit, current))  # missing attribute
django.template.base.VariableDoesNotExist: Failed lookup for key [name] in <URLResolver <module 'rest_framework.urls' from 'C:\\Users\\Maxqu\\Anaconda3\\envs\\puppy-webshop\\lib\\site-packages\\rest_framework\\urls.py'> (rest_framework:rest_framework) 'api-auth/'>
Exception while resolving variable 'name' in template 'unknown'.
Traceback (most recent call last):
  File "C:\Users\Maxqu\Anaconda3\envs\puppy-webshop\lib\site-packages\django\core\handlers\exception.py", line 34, in inner
    response = get_response(request)
  File "C:\Users\Maxqu\Anaconda3\envs\puppy-webshop\lib\site-packages\django\core\handlers\base.py", line 111, in _get_response
    resolver_match = resolver.resolve(request.path_info)
  File "C:\Users\Maxqu\Anaconda3\envs\puppy-webshop\lib\site-packages\django\urls\resolvers.py", line 520, in resolve
    raise Resolver404({'tried': tried, 'path': new_path})
django.urls.exceptions.Resolver404: {'tried': [[<URLResolver <module 'shop.urls' from 'C:\\Users\\Maxqu\\PycharmProjects\\puppy-webshop\\backend\\shop\\urls.py'> (None:None) 'shop/'>], [<URLResolver <URLPattern list> (admin:admin) 'admin/'>], [<URLPattern 'token-auth/'>], [<URLResolver <module 'rest_framework.urls' from 'C:\\Users\\Maxqu\\Anaconda3\\envs\\puppy-webshop\\lib\\site-packages\\rest_framework\\urls.py'> (rest_framework:rest_framework) 'api-auth/'>], [<URLResolver <module 'letsencrypt.urls' from 'C:\\Users\\Maxqu\\Anaconda3\\envs\\puppy-webshop\\lib\\site-packages\\letsencrypt\\urls.py'> (None:None) '\.well-known/'>]], 'path': '.well-known/'}

During handling of the above exception, another exception occurred:

Traceback (most recent call last):
  File "C:\Users\Maxqu\Anaconda3\envs\puppy-webshop\lib\site-packages\django\template\base.py", line 829, in _resolve_lookup
    current = current[bit]
TypeError: 'URLResolver' object is not subscriptable

During handling of the above exception, another exception occurred:

Traceback (most recent call last):
  File "C:\Users\Maxqu\Anaconda3\envs\puppy-webshop\lib\site-packages\django\template\base.py", line 837, in _resolve_lookup
    current = getattr(current, bit)
AttributeError: 'URLResolver' object has no attribute 'name'

During handling of the above exception, another exception occurred:

Traceback (most recent call last):
  File "C:\Users\Maxqu\Anaconda3\envs\puppy-webshop\lib\site-packages\django\template\base.py", line 843, in _resolve_lookup
    current = current[int(bit)]
ValueError: invalid literal for int() with base 10: 'name'

During handling of the above exception, another exception occurred:

Traceback (most recent call last):
  File "C:\Users\Maxqu\Anaconda3\envs\puppy-webshop\lib\site-packages\django\template\base.py", line 850, in _resolve_lookup
    (bit, current))  # missing attribute
django.template.base.VariableDoesNotExist: Failed lookup for key [name] in <URLResolver <module 'letsencrypt.urls' from 'C:\\Users\\Maxqu\\Anaconda3\\envs\\puppy-webshop\\lib\\site-packages\\letsencrypt\\urls.py'> (None:None) '\.well-known/'>
Not Found: /.well-known/
"GET /.well-known/ HTTP/1.1" 404 2415
